Workbook

Sheet Sheet1
A1: EJ発注番号 | B1: 発注担当者 | C1: EJ連番 | D1: EJ品目コード | E1: EJ品目名 | F1: EJ数 | G1: EJステータス | H1: EJ発注種別 | I1: EJ納期 | J1: EJ仕入先コード | K1: rBOM発注番号+行番号 | L1: 受入済み番号（参考） | O1: 単価
A2: E8595256 | B2: 4 | C2: 1 | D2: BRT-140X210-5 | E2: TAPER ROLLER BEARING(HR32028XJ) | F2: 2 | G2: 2 | H2: 1 | I2: 46052 | J2: 3062 | K2: 000051400+001
A3: E8674119 | B3: J | C3: 1 | D3: FPS-17-001AA | E3: JOINT | F3: 204 | G3: 2 | H3: 1 | I3: 45999 | K3: 000020764+001 | L3: 000020764+001
A4: E8674119 | B4: J | C4: 1 | D4: FPS-17-001AA | E4: JOINT | F4: 84 | G4: 2 | H4: 1 | I4: 45999 | K4: 000020847+001 | L4: 000020764+001
A5: E8674119 | B5: J | C5: 1 | D5: FPS-17-001AA | E5: JOINT | F5: 22 | G5: 2 | H5: 1 | I5: 45999 | K5: 000020981+001 | L5: 000020764+001
A6: E8674119 | B6: J | C6: 1 | D6: FPS-17-001AA | E6: JOINT | F6: 96 | G6: 2 | H6: 1 | I6: 45999 | K6: 000023801+001 | L6: 000020764+001
A7: E8674119 | B7: J | C7: 1 | D7: FPS-17-001AA | E7: JOINT | F7: 60 | G7: 2 | H7: 1 | I7: 45999 | K7: 000025429+001 | L7: 000020764+001
A8: E8674119 | B8: J | C8: 1 | D8: FPS-17-001AA | E8: JOINT | F8: 84 | G8: 2 | H8: 1 | I8: 45999 | K8: 000025429+002 | L8: 000020764+001
A9: E8674120 | B9: J | C9: 1 | D9: FPS-17-001AA | E9: JOINT | F9: 96 | G9: 2 | H9: 1 | I9: 46031 | K9: 000021579+001
A10: E8674120 | B10: J | C10: 2 | D10: FPS-17-001AA | E10: JOINT | F10: 84 | G10: 2 | H10: 1 | I10: 46031 | K10: 000021758+001
A11: E8674120 | B11: J | C11: 3 | D11: FPS-17-001AA | E11: JOINT | F11: 96 | G11: 2 | H11: 1 | I11: 46031 | K11: 000021865+001
A12: E8674120 | B12: J | C12: 4 | D12: FPS-17-001AA | E12: JOINT | F12: 96 | G12: 2 | H12: 1 | I12: 46031 | K12: 000022039+001
A13: E8674120 | B13: J | C13: 5 | D13: FPS-17-001AA | E13: JOINT | F13: 108 | G13: 2 | H13: 1 | I13: 46031 | K13: 000022176+001
A14: E8674120 | B14: J | C14: 6 | D14: FPS-17-001AA | E14: JOINT | F14: 70 | G14: 2 | H14: 1 | I14: 46031 | K14: 000022303+001
A15: E8674121 | B15: J | C15: 1 | D15: FPS-17-001AA | E15: JOINT | F15: 16 | G15: 2 | H15: 1 | I15: 46062 | K15: 000022934+001
A16: E8674121 | B16: J | C16: 4 | D16: FPS-17-001AA | E16: JOINT | F16: 378 | G16: 2 | H16: 1 | I16: 46062 | J16: =N16 -> 3908 | K16: 000051402+001 | N16: =VLOOKUP(A16,Sheet2!A:B,2,) -> 3908
A17: E8674121 | B17: J | C17: 2 | D17: FPS-17-001AA | E17: JOINT | F17: 96 | G17: 2 | H17: 1 | I17: 46062 | K17: 000023061+001
A18: E8674121 | B18: J | C18: 3 | D18: FPS-17-001AA | E18: JOINT | F18: 60 | G18: 2 | H18: 1 | I18: 46062 | K18: 000023161+001
A19: E8714174 | B19: S | C19: 1 | D19: EP-403DB | E19: ｼﾝｸﾛﾅｽﾓｰﾀ(PTM-24AG-54 AC24V ｼｬﾌﾄｶｲｿﾞｳ) | F19: 14 | G19: 2 | H19: 1 | I19: 45975 | K19: 000020677+001 | L19: 000025352+001
A20: E8714174 | B20: S | C20: 1 | D20: EP-403DB | E20: ｼﾝｸﾛﾅｽﾓｰﾀ(PTM-24AG-54 AC24V ｼｬﾌﾄｶｲｿﾞｳ) | F20: 19 | G20: 2 | H20: 1 | I20: 45975 | K20: 000023712+001 | L20: 000025352+001
A21: E8714174 | B21: S | C21: 1 | D21: EP-403DB | E21: ｼﾝｸﾛﾅｽﾓｰﾀ(PTM-24AG-54 AC24V ｼｬﾌﾄｶｲｿﾞｳ) | F21: 8 | G21: 2 | H21: 1 | I21: 45975 | K21: 000025352+001 | L21: 000025352+001 | N21: 8？
A22: E8714174 | B22: S | C22: 1 | D22: EP-403DB | E22: ｼﾝｸﾛﾅｽﾓｰﾀ(PTM-24AG-54 AC24V ｼｬﾌﾄｶｲｿﾞｳ) | F22: 9 | G22: 2 | H22: 1 | I22: 45975 | K22: 000025352+002 | L22: 000025352+001
A23: E8749615 | B23: 1 | C23: 1 | D23: MA-12-426LB30 | E23: PIECE SKD | F23: 1500 | G23: 2 | H23: 1 | I23: 46416 | J23: 3199 | K23: 000051403+001
A24: E8749616 | B24: 1 | C24: 1 | D24: MA-12-426LB38 | E24: PIECE | F24: 1500 | G24: 2 | H24: 1 | I24: 46416 | J24: 3199 | K24: 000051403+002
A25: E8760544 | B25: R | C25: 1 | D25: EP-412AA | E25: SLIP RING ﾒﾙｺﾀｯｸ430 | F25: 90 | G25: 2 | H25: 1 | I25: 46001 | K25: 000023305+001 | L25: 000023305+001
A26: E8760545 | B26: R | C26: 1 | D26: EP-412AA | E26: SLIP RING ﾒﾙｺﾀｯｸ430 | F26: 80 | G26: 2 | H26: 1 | I26: 46031 | J26: 1420 | K26: 000051405+001
A27: E8760546 | B27: R | C27: 1 | D27: EP-412AA | E27: SLIP RING ﾒﾙｺﾀｯｸ430 | F27: 90 | G27: 2 | H27: 1 | I27: 46063 | J27: 1420 | K27: 000051405+002
A28: E8760547 | B28: R | C28: 1 | D28: EP-412AA | E28: SLIP RING ﾒﾙｺﾀｯｸ430 | F28: 90 | G28: 2 | H28: 1 | I28: 46091 | J28: 1420 | K28: 000051405+003
A29: E8760598 | B29: KK | C29: 1 | F29: 1 | K29: 000023270+001
A30: E8760599 | B30: KK | C30: 1 | F30: 1 | K30: 000023295+001
A31: E8764746 | B31: W | C31: 1 | D31: FSP-21-001AA | E31: CUTTER HOLDER PLATE | F31: 24 | G31: 2 | H31: 1 | I31: 46001 | K31: 000020827+001 | L31: 000020827+001
A32: E8764746 | B32: W | C32: 1 | D32: FSP-21-001AA | E32: CUTTER HOLDER PLATE | F32: 7 | G32: 2 | H32: 1 | I32: 46001 | K32: 000020921+001 | L32: 000020827+001
A33: E8764746 | B33: W | C33: 1 | D33: FSP-21-001AA | E33: CUTTER HOLDER PLATE | F33: 6 | G33: 2 | H33: 1 | I33: 46001 | K33: 000021047+001 | L33: 000020827+001
A34: E8764746 | B34: W | C34: 1 | D34: FSP-21-001AA | E34: CUTTER HOLDER PLATE | F34: 8 | G34: 2 | H34: 1 | I34: 46001 | K34: 000023852+001 | L34: 000020827+001
A35: E8764746 | B35: W | C35: 1 | D35: FSP-21-001AA | E35: CUTTER HOLDER PLATE | F35: 5 | G35: 2 | H35: 1 | I35: 46001 | K35: 000025345+001 | L35: 000020827+001
A36: E8772716 | B36: S | C36: 1 | D36: E-30460AB | E36: FMC40 DRIVE BOARD | F36: 42 | G36: 2 | H36: 2 | I36: 46016 | K36: 000021325+004
A37: E8772724 | B37: S | C37: 1 | D37: E-30441A | E37: CPU BOARD FOR ｺﾝﾄﾛ-ﾗ-( FMC-40 ) | F37: 4 | G37: 2 | H37: 2 | I37: 46016 | K37: 000021325+003 | L37: 000021325+003
A38: E8772733 | B38: S | C38: 1 | D38: E-30432CA | E38: POWER CONTROL BOARD | F38: 3 | G38: 2 | H38: 2 | I38: 46016 | K38: 000021325+002 | L38: 000021325+002
A39: E8772909 | B39: J | C39: 1 | D39: FPS-17-001AA | E39: JOINT | F39: 550 | G39: 2 | H39: 1 | I39: 46090 | J39: 3908 | K39: 000051407+001
A40: E8772910 | B40: J | C40: 1 | D40: FPS-17-001AA | E40: JOINT | F40: 550 | G40: 2 | H40: 1 | I40: 46121 | J40: 3908 | K40: 000051407+002
...

Sheet xSheet1
A1: EJ発注番号 | B1: 発注担当者 | C1: EJ連番 | D1: EJ品目コード | E1: EJ品目名 | F1: EJ数 | G1: EJステータス | H1: EJ発注種別 | I1: EJ納期 | J1: EJ仕入先コード | K1: rBOM発注番号+行番号 | L1: 受入済み番号（参考） | O1: 単価
A2: E8595256 | B2: 4 | C2: 1 | D2: BRT-140X210-5 | E2: TAPER ROLLER BEARING(HR32028XJ) | F2: 2 | G2: 2 | H2: 1 | I2: 46052 | J2: 3062 | K2: 000051400+001
A3: E8674119 | B3: J | C3: 1 | D3: FPS-17-001AA | E3: JOINT | F3: 204 | G3: 2 | H3: 1 | I3: 45999 | K3: 000020764+001 | L3: 000020764+001
A4: E8674119 | B4: J | C4: 1 | D4: FPS-17-001AA | E4: JOINT | F4: 84 | G4: 2 | H4: 1 | I4: 45999 | K4: 000020847+001 | L4: 000020764+001
A5: E8674119 | B5: J | C5: 1 | D5: FPS-17-001AA | E5: JOINT | F5: 22 | G5: 2 | H5: 1 | I5: 45999 | K5: 000020981+001 | L5: 000020764+001
A6: E8674119 | B6: J | C6: 1 | D6: FPS-17-001AA | E6: JOINT | F6: 96 | G6: 2 | H6: 1 | I6: 45999 | K6: 000023801+001 | L6: 000020764+001
A7: E8674119 | B7: J | C7: 1 | D7: FPS-17-001AA | E7: JOINT | F7: 60 | G7: 2 | H7: 1 | I7: 45999 | K7: 000025429+001 | L7: 000020764+001
A8: E8674119 | B8: J | C8: 1 | D8: FPS-17-001AA | E8: JOINT | F8: 84 | G8: 2 | H8: 1 | I8: 45999 | K8: 000025429+002 | L8: 000020764+001
A9: E8674120 | B9: J | C9: 1 | D9: FPS-17-001AA | E9: JOINT | F9: 96 | G9: 2 | H9: 1 | I9: 46031 | K9: 000021579+001
A10: E8674120 | B10: J | C10: 2 | D10: FPS-17-001AA | E10: JOINT | F10: 84 | G10: 2 | H10: 1 | I10: 46031 | K10: 000021758+001
A11: E8674120 | B11: J | C11: 3 | D11: FPS-17-001AA | E11: JOINT | F11: 96 | G11: 2 | H11: 1 | I11: 46031 | K11: 000021865+001
A12: E8674120 | B12: J | C12: 4 | D12: FPS-17-001AA | E12: JOINT | F12: 96 | G12: 2 | H12: 1 | I12: 46031 | K12: 000022039+001
A13: E8674120 | B13: J | C13: 5 | D13: FPS-17-001AA | E13: JOINT | F13: 108 | G13: 2 | H13: 1 | I13: 46031 | K13: 000022176+001
A14: E8674120 | B14: J | C14: 6 | D14: FPS-17-001AA | E14: JOINT | F14: 70 | G14: 2 | H14: 1 | I14: 46031 | K14: 000022303+001
A15: E8674121 | B15: J | C15: 1 | D15: FPS-17-001AA | E15: JOINT | F15: 16 | G15: 2 | H15: 1 | I15: 46062 | K15: 000022934+001
A16: E8674121 | B16: J | C16: 4 | D16: FPS-17-001AA | E16: JOINT | F16: 378 | G16: 2 | H16: 1 | I16: 46062 | J16: =N16 -> 3908 | K16: 000022934+001 | N16: =VLOOKUP(A16,Sheet2!A:B,2,) -> 3908
A17: E8674121 | B17: J | C17: 2 | D17: FPS-17-001AA | E17: JOINT | F17: 96 | G17: 2 | H17: 1 | I17: 46062 | K17: 000023061+001
A18: E8674121 | B18: J | C18: 3 | D18: FPS-17-001AA | E18: JOINT | F18: 60 | G18: 2 | H18: 1 | I18: 46062 | K18: 000023161+001
A19: E8714174 | B19: S | C19: 1 | D19: EP-403DB | E19: ｼﾝｸﾛﾅｽﾓｰﾀ(PTM-24AG-54 AC24V ｼｬﾌﾄｶｲｿﾞｳ) | F19: 14 | G19: 2 | H19: 1 | I19: 45975 | K19: 000020677+001 | L19: 000025352+001
A20: E8714174 | B20: S | C20: 1 | D20: EP-403DB | E20: ｼﾝｸﾛﾅｽﾓｰﾀ(PTM-24AG-54 AC24V ｼｬﾌﾄｶｲｿﾞｳ) | F20: 19 | G20: 2 | H20: 1 | I20: 45975 | K20: 000023712+001 | L20: 000025352+001
A21: E8714174 | B21: S | C21: 1 | D21: EP-403DB | E21: ｼﾝｸﾛﾅｽﾓｰﾀ(PTM-24AG-54 AC24V ｼｬﾌﾄｶｲｿﾞｳ) | F21: 8 | G21: 2 | H21: 1 | I21: 45975 | K21: 000025352+001 | L21: 000025352+001 | N21: 8？
A22: E8714174 | B22: S | C22: 1 | D22: EP-403DB | E22: ｼﾝｸﾛﾅｽﾓｰﾀ(PTM-24AG-54 AC24V ｼｬﾌﾄｶｲｿﾞｳ) | F22: 9 | G22: 2 | H22: 1 | I22: 45975 | K22: 000025352+002 | L22: 000025352+001
A23: E8749615 | B23: 1 | C23: 1 | D23: MA-12-426LB30 | E23: PIECE SKD | F23: 1500 | G23: 2 | H23: 1 | I23: 46416 | J23: 3199 | K23: 000051403+001
A24: E8749616 | B24: 1 | C24: 1 | D24: MA-12-426LB38 | E24: PIECE | F24: 1500 | G24: 2 | H24: 1 | I24: 46416 | J24: 3199 | K24: 000051403+002
A25: E8760544 | B25: R | C25: 1 | D25: EP-412AA | E25: SLIP RING ﾒﾙｺﾀｯｸ430 | F25: 90 | G25: 2 | H25: 1 | I25: 46001 | K25: 000023305+001 | L25: 000023305+001
A26: E8760545 | B26: R | C26: 1 | D26: EP-412AA | E26: SLIP RING ﾒﾙｺﾀｯｸ430 | F26: 80 | G26: 2 | H26: 1 | I26: 46031 | J26: 1420 | K26: 000051405+001
A27: E8760546 | B27: R | C27: 1 | D27: EP-412AA | E27: SLIP RING ﾒﾙｺﾀｯｸ430 | F27: 90 | G27: 2 | H27: 1 | I27: 46063 | J27: 1420 | K27: 000051405+002
A28: E8760547 | B28: R | C28: 1 | D28: EP-412AA | E28: SLIP RING ﾒﾙｺﾀｯｸ430 | F28: 90 | G28: 2 | H28: 1 | I28: 46091 | J28: 1420 | K28: 000051405+003
A29: E8760598 | B29: KK | C29: 1 | F29: 1 | K29: 000023270+001
A30: E8760599 | B30: KK | C30: 1 | F30: 1 | K30: 000023295+001
A31: E8764746 | B31: W | C31: 1 | D31: FSP-21-001AA | E31: CUTTER HOLDER PLATE | F31: 24 | G31: 2 | H31: 1 | I31: 46001 | K31: 000020827+001 | L31: 000020827+001
A32: E8764746 | B32: W | C32: 1 | D32: FSP-21-001AA | E32: CUTTER HOLDER PLATE | F32: 7 | G32: 2 | H32: 1 | I32: 46001 | K32: 000020921+001 | L32: 000020827+001
A33: E8764746 | B33: W | C33: 1 | D33: FSP-21-001AA | E33: CUTTER HOLDER PLATE | F33: 6 | G33: 2 | H33: 1 | I33: 46001 | K33: 000021047+001 | L33: 000020827+001
A34: E8764746 | B34: W | C34: 1 | D34: FSP-21-001AA | E34: CUTTER HOLDER PLATE | F34: 8 | G34: 2 | H34: 1 | I34: 46001 | K34: 000023852+001 | L34: 000020827+001
A35: E8764746 | B35: W | C35: 1 | D35: FSP-21-001AA | E35: CUTTER HOLDER PLATE | F35: 5 | G35: 2 | H35: 1 | I35: 46001 | K35: 000025345+001 | L35: 000020827+001
A36: E8772716 | B36: S | C36: 1 | D36: E-30460AB | E36: FMC40 DRIVE BOARD | F36: 42 | G36: 2 | H36: 2 | I36: 46016 | K36: 000021325+004
A37: E8772724 | B37: S | C37: 1 | D37: E-30441A | E37: CPU BOARD FOR ｺﾝﾄﾛ-ﾗ-( FMC-40 ) | F37: 4 | G37: 2 | H37: 2 | I37: 46016 | K37: 000021325+003 | L37: 000021325+003
A38: E8772733 | B38: S | C38: 1 | D38: E-30432CA | E38: POWER CONTROL BOARD | F38: 3 | G38: 2 | H38: 2 | I38: 46016 | K38: 000021325+002 | L38: 000021325+002
A39: E8772909 | B39: J | C39: 1 | D39: FPS-17-001AA | E39: JOINT | F39: 550 | G39: 2 | H39: 1 | I39: 46090 | J39: 3908 | K39: 000051407+001
A40: E8772910 | B40: J | C40: 1 | D40: FPS-17-001AA | E40: JOINT | F40: 550 | G40: 2 | H40: 1 | I40: 46121 | J40: 3908 | K40: 000051407+002
...

Sheet 注意事項
A1: EJ発注において、2025年10月以前の納期分はマッピングされていません。 そのため、受入時に都度手配を作成して対応する予定です。 ※古い納期（2015年～多数の発注書がある）が残り続けているためです。
A3: マスタの仕入先や単価が異なる箇所については、手修正を行っています。

Sheet Sheet2
A1: 172.17.107.102/expj(Direct) : 2025/12/15 13:10:59
A2: PUCH_ODR_CD | B2: VEND_CD | C2: UNIT_COST
A3: E8049257 | B3: 3399 | C3: 8475
A4: E8595256 | B4: 3062 | C4: 12400
A5: E8630403 | B5: 3264 | C5: 8843
A6: E8630404 | B6: 3264 | C6: 8843
A7: E8630405 | B7: 3264 | C7: 8843
A8: E8652411 | B8: 3399 | C8: 34790
A9: E8652412 | B9: 3399 | C9: 35230
A10: E8674119 | B10: 3908 | C10: 580
A11: E8674120 | B11: 3908 | C11: 580
A12: E8674121 | B12: 3908 | C12: 580
A13: E8714174 | B13: 2950 | C13: 4000
A14: E8749570 | B14: 3318 | C14: 141895
... A8014: E9050785 | B8014: 3724 | C8014: 748
